Workbook
Name Slicer_Department_Referral: #N/A
Name Slicer_Month: #N/A
Name Slicer_Year: #N/A

Sheet Raw_Data
A1: Patient Id | B1: Patient Admission Date | C1: Patient First Inital | D1: Patient Last Name | E1: Patient Gender | F1: Patient Age | G1: Patient Race | H1: Department Referral | I1: Patient Admission Flag | J1: Patient Satisfaction Score | K1: Patient Waittime
A2: 516-79-5879 | B2: 45017.004 | C2: X | D2: Middleditch | E2: Female | F2: 58 | G2: White | H2: None | I2: TRUE | J2: 1 | K2: 18
A3: 255-78-2350 | B3: 45017.088 | C3: B | D3: Schubuser | E3: M | F3: 22 | G3: Declined to Identify | H3: None | I3: FALSE | K3: 10
A4: 785-87-9129 | B4: 45017.09 | C4: V | D4: Kershaw | E4: M | F4: 56 | G4: African American | H4: None | I4: FALSE | K4: 57
A5: 896-54-2877 | B5: 45017.165 | C5: L | D5: Ellerby | E5: Female | F5: 60 | G5: Declined to Identify | H5: Orthopedics | I5: FALSE | K5: 31
A6: 429-27-5915 | B6: 45017.257 | C6: C | D6: Ravenscroft | E6: F | F6: 40 | G6: White | H6: General Practice | I6: FALSE | J6: 6 | K6: 18
A7: 934-86-5957 | B7: 45017.297 | C7: V | D7: Kershaw | E7: F | F7: 58 | G7: White | H7: General Practice | I7: TRUE | J7: 0 | K7: 27
A8: 855-20-3905 | B8: 45017.331 | C8: F | D8: Garfield | E8: M | F8: 14 | G8: Two or More Races | H8: None | I8: TRUE | J8: 9 | K8: 31
A9: 204-20-3676 | B9: 45017.338 | C9: M | D9: Stanlack | E9: M | F9: 55 | G9: White | H9: None | I9: FALSE | J9: 7 | K9: 44
A10: 716-23-4315 | B10: 45017.374 | C10: L | D10: Jessop | E10: Male | F10: 43 | G10: White | H10: General Practice | I10: FALSE | J10: 6 | K10: 53
A11: 947-59-1554 | B11: 45017.501 | C11: Q | D11: Cholmondeley | E11: F | F11: 67 | G11: Native American/Alaska Native | H11: None | I11: TRUE | J11: 2 | K11: 16
A12: 466-34-9495 | B12: 45017.617 | C12: M | D12: Upperton | E12: Female | F12: 20 | G12: White | H12: None | I12: FALSE | K12: 30
A13: 706-60-4656 | B13: 45017.778 | C13: R | D13: Aldridge | E13: M | F13: 11 | G13: Asian | H13: None | I13: FALSE | K13: 40
A14: 125-98-3065 | B14: 45017.799 | C14: O | D14: Stanlack | E14: M | F14: 45 | G14: Native American/Alaska Native | H14: None | I14: FALSE | J14: 3 | K14: 37
A15: 661-47-3607 | B15: 45018.037 | C15: J | D15: Honeysett | E15: F | F15: 79 | G15: White | H15: None | I15: FALSE | K15: 37
A16: 642-11-2783 | B16: 45018.098 | C16: R | D16: Oakden | E16: Male | F16: 63 | G16: Pacific Islander | H16: None | I16: TRUE | J16: 3 | K16: 38
A17: 717-73-3147 | B17: 45018.101 | C17: B | D17: Loxley | E17: F | F17: 28 | G17: White | H17: None | I17: FALSE | K17: 34
A18: 777-17-5837 | B18: 45018.119 | C18: R | D18: Ollerton | E18: Male | F18: 32 | G18: Declined to Identify | H18: Orthopedics | I18: TRUE | J18: 1 | K18: 51
A19: 631-76-7508 | B19: 45018.142 | C19: B | D19: Gwillim | E19: M | F19: 36 | G19: Declined to Identify | H19: Gastroenterology | I19: TRUE | K19: 55
A20: 638-31-9790 | B20: 45018.172 | C20: Y | D20: Stanlack | E20: F | F20: 20 | G20: White | H20: None | I20: TRUE | K20: 31
A21: 344-73-8765 | B21: 45018.24 | C21: R | D21: Kershaw | E21: M | F21: 31 | G21: Two or More Races | H21: None | I21: TRUE | K21: 59
A22: 971-62-4725 | B22: 45018.268 | C22: H | D22: Crebo | E22: Male | F22: 20 | G22: White | H22: None | I22: TRUE | K22: 57
A23: 292-62-5172 | B23: 45018.324 | C23: Z | D23: Jessop | E23: M | F23: 13 | G23: African American | H23: None | I23: FALSE | K23: 21
A24: 340-98-8339 | B24: 45018.419 | C24: U | D24: Buff | E24: Female | F24: 56 | G24: Two or More Races | H24: General Practice | I24: FALSE | K24: 57
A25: 774-10-5039 | B25: 45018.433 | C25: U | D25: Tunstall | E25: Male | F25: 56 | G25: Declined to Identify | H25: None | I25: FALSE | K25: 32
A26: 289-39-3879 | B26: 45018.538 | C26: A | D26: Dewhirst | E26: F | F26: 50 | G26: Two or More Races | H26: None | I26: TRUE | J26: 10 | K26: 48
A27: 120-52-2786 | B27: 45018.578 | C27: A | D27: Brixey | E27: Female | F27: 44 | G27: White | H27: General Practice | I27: FALSE | K27: 20
A28: 177-63-9844 | B28: 45018.589 | C28: N | D28: Stanlack | E28: F | F28: 50 | G28: Unknown | H28: None | I28: TRUE | K28: 10
A29: 858-87-7114 | B29: 45018.881 | C29: P | D29: Oakden | E29: F | F29: 9 | G29: Asian | H29: None | I29: TRUE | J29: 4 | K29: 44
A30: 358-25-7655 | B30: 45018.929 | C30: A | D30: Corpes | E30: Male | F30: 20 | G30: Native American/Alaska Native | H30: None | I30: TRUE | K30: 57
A31: 457-29-4012 | B31: 45018.944 | C31: P | D31: Carraway | E31: M | F31: 79 | G31: African American | H31: None | I31: TRUE | K31: 26
A32: 284-67-8189 | B32: 45018.957 | C32: F | D32: Hathaway | E32: Male | F32: 21 | G32: White | H32: None | I32: FALSE | K32: 43
A33: 584-77-9159 | B33: 45018.979 | C33: D | D33: Corpes | E33: F | F33: 12 | G33: White | H33: None | I33: FALSE | K33: 52
A34: 980-10-7575 | B34: 45019.003 | C34: J | D34: Greenhalgh | E34: M | F34: 4 | G34: Asian | H34: Orthopedics | I34: FALSE | J34: 3 | K34: 51
A35: 434-99-7159 | B35: 45019.021 | C35: L | D35: Ollerton | E35: Female | F35: 18 | G35: Declined to Identify | H35: None | I35: FALSE | J35: 5 | K35: 41
A36: 522-74-8477 | B36: 45019.022 | C36: J | D36: Garfield | E36: Male | F36: 49 | G36: Unknown | H36: None | I36: TRUE | K36: 44
A37: 872-84-7136 | B37: 45019.045 | C37: U | D37: Greenhalgh | E37: Female | F37: 67 | G37: African American | H37: Orthopedics | I37: TRUE | K37: 16
A38: 871-43-5513 | B38: 45019.065 | C38: G | D38: Loxley | E38: Female | F38: 71 | G38: Asian | H38: None | I38: TRUE | K38: 40
A39: 458-92-6638 | B39: 45019.321 | C39: S | D39: Upperton | E39: M | F39: 28 | G39: White | H39: None | I39: FALSE | K39: 24
A40: 244-79-2094 | B40: 45019.323 | C40: Q | D40: Silverlock | E40: Female | F40: 63 | G40: Asian | H40: General Practice | I40: TRUE | J40: 5 | K40: 35
...

Sheet Cleaning
A1: Patient Id | B1: Admission Date | C1: Admission Hour | D1: Month | E1: Year | F1: Month-Year | G1: Patient Full Name | H1: Gender (Clean) | I1: Age | J1: Age Group | K1: Race | L1: Department Referral | M1: Admission Status | N1: Satisfaction Score | O1: Wait Time (min) | P1: Patient Attend Status
A2: =Raw_Data!A2 -> 516-79-5879 | B2: =Raw_Data!B2 -> 45017.004 | C2: =HOUR(Raw_Data!B2) -> 0 | D2: =TEXT(Raw_Data!B2,"mmm") -> Apr | E2: =YEAR(Raw_Data!B2) -> 2023 | F2: =TEXT(Raw_Data!B2,"mmm-yy") -> Apr-23 | G2: =PROPER(Raw_Data!C2&". "&Raw_Data!D2) -> X. Middleditch | H2: =IF(OR(Raw_Data!E2="M",Raw_Data!E2="Male"),"Male",IF(OR(Raw_Data!E2="F",Raw_Data!E2="Female"),"Female","Not Confirmed")) -> Female | I2: =Raw_Data!F2 -> 58 | J2: =FLOOR(Raw_Data!F2,10)&"-"&FLOOR(Raw_Data!F2,10)+9 -> 50-59 | K2: =Raw_Data!G2 -> White | L2: =Raw_Data!H2 -> None | M2: =IF(Raw_Data!I2=TRUE,"Admitted","Not Admitted") -> Admitted | N2: =IF(Raw_Data!J2="","Not Rated",Raw_Data!J2) -> 1 | O2: =Raw_Data!K2 -> 18 | P2: =IF(Raw_Data!K2<=30,"Within Time","Delayed") -> Within Time
A3: =Raw_Data!A3 -> 255-78-2350 | B3: =Raw_Data!B3 -> 45017.088 | C3: =HOUR(Raw_Data!B3) -> 2 | D3: =TEXT(Raw_Data!B3,"mmm") -> Apr | E3: =YEAR(Raw_Data!B3) -> 2023 | F3: =TEXT(Raw_Data!B3,"mmm-yy") -> Apr-23 | G3: =PROPER(Raw_Data!C3&". "&Raw_Data!D3) -> B. Schubuser | H3: =IF(OR(Raw_Data!E3="M",Raw_Data!E3="Male"),"Male",IF(OR(Raw_Data!E3="F",Raw_Data!E3="Female"),"Female","Not Confirmed")) -> Male | I3: =Raw_Data!F3 -> 22 | J3: =FLOOR(Raw_Data!F3,10)&"-"&FLOOR(Raw_Data!F3,10)+9 -> 20-29 | K3: =Raw_Data!G3 -> Declined to Identify | L3: =Raw_Data!H3 -> None | M3: =IF(Raw_Data!I3=TRUE,"Admitted","Not Admitted") -> Not Admitted | N3: =IF(Raw_Data!J3="","Not Rated",Raw_Data!J3) -> Not Rated | O3: =Raw_Data!K3 -> 10 | P3: =IF(Raw_Data!K3<=30,"Within Time","Delayed") -> Within Time
A4: =Raw_Data!A4 -> 785-87-9129 | B4: =Raw_Data!B4 -> 45017.09 | C4: =HOUR(Raw_Data!B4) -> 2 | D4: =TEXT(Raw_Data!B4,"mmm") -> Apr | E4: =YEAR(Raw_Data!B4) -> 2023 | F4: =TEXT(Raw_Data!B4,"mmm-yy") -> Apr-23 | G4: =PROPER(Raw_Data!C4&". "&Raw_Data!D4) -> V. Kershaw | H4: =IF(OR(Raw_Data!E4="M",Raw_Data!E4="Male"),"Male",IF(OR(Raw_Data!E4="F",Raw_Data!E4="Female"),"Female","Not Confirmed")) -> Male | I4: =Raw_Data!F4 -> 56 | J4: =FLOOR(Raw_Data!F4,10)&"-"&FLOOR(Raw_Data!F4,10)+9 -> 50-59 | K4: =Raw_Data!G4 -> African American | L4: =Raw_Data!H4 -> None | M4: =IF(Raw_Data!I4=TRUE,"Admitted","Not Admitted") -> Not Admitted | N4: =IF(Raw_Data!J4="","Not Rated",Raw_Data!J4) -> Not Rated | O4: =Raw_Data!K4 -> 57 | P4: =IF(Raw_Data!K4<=30,"Within Time","Delayed") -> Delayed
A5: =Raw_Data!A5 -> 896-54-2877 | B5: =Raw_Data!B5 -> 45017.165 | C5: =HOUR(Raw_Data!B5) -> 3 | D5: =TEXT(Raw_Data!B5,"mmm") -> Apr | E5: =YEAR(Raw_Data!B5) -> 2023 | F5: =TEXT(Raw_Data!B5,"mmm-yy") -> Apr-23 | G5: =PROPER(Raw_Data!C5&". "&Raw_Data!D5) -> L. Ellerby | H5: =IF(OR(Raw_Data!E5="M",Raw_Data!E5="Male"),"Male",IF(OR(Raw_Data!E5="F",Raw_Data!E5="Female"),"Female","Not Confirmed")) -> Female | I5: =Raw_Data!F5 -> 60 | J5: =FLOOR(Raw_Data!F5,10)&"-"&FLOOR(Raw_Data!F5,10)+9 -> 60-69 | K5: =Raw_Data!G5 -> Declined to Identify | L5: =Raw_Data!H5 -> Orthopedics | M5: =IF(Raw_Data!I5=TRUE,"Admitted","Not Admitted") -> Not Admitted | N5: =IF(Raw_Data!J5="","Not Rated",Raw_Data!J5) -> Not Rated | O5: =Raw_Data!K5 -> 31 | P5: =IF(Raw_Data!K5<=30,"Within Time","Delayed") -> Delayed
A6: =Raw_Data!A6 -> 429-27-5915 | B6: =Raw_Data!B6 -> 45017.257 | C6: =HOUR(Raw_Data!B6) -> 6 | D6: =TEXT(Raw_Data!B6,"mmm") -> Apr | E6: =YEAR(Raw_Data!B6) -> 2023 | F6: =TEXT(Raw_Data!B6,"mmm-yy") -> Apr-23 | G6: =PROPER(Raw_Data!C6&". "&Raw_Data!D6) -> C. Ravenscroft | H6: =IF(OR(Raw_Data!E6="M",Raw_Data!E6="Male"),"Male",IF(OR(Raw_Data!E6="F",Raw_Data!E6="Female"),"Female","Not Confirmed")) -> Female | I6: =Raw_Data!F6 -> 40 | J6: =FLOOR(Raw_Data!F6,10)&"-"&FLOOR(Raw_Data!F6,10)+9 -> 40-49 | K6: =Raw_Data!G6 -> White | L6: =Raw_Data!H6 -> General Practice | M6: =IF(Raw_Data!I6=TRUE,"Admitted","Not Admitted") -> Not Admitted | N6: =IF(Raw_Data!J6="","Not Rated",Raw_Data!J6) -> 6 | O6: =Raw_Data!K6 -> 18 | P6: =IF(Raw_Data!K6<=30,"Within Time","Delayed") -> Within Time
A7: =Raw_Data!A7 -> 934-86-5957 | B7: =Raw_Data!B7 -> 45017.297 | C7: =HOUR(Raw_Data!B7) -> 7 | D7: =TEXT(Raw_Data!B7,"mmm") -> Apr | E7: =YEAR(Raw_Data!B7) -> 2023 | F7: =TEXT(Raw_Data!B7,"mmm-yy") -> Apr-23 | G7: =PROPER(Raw_Data!C7&". "&Raw_Data!D7) -> V. Kershaw | H7: =IF(OR(Raw_Data!E7="M",Raw_Data!E7="Male"),"Male",IF(OR(Raw_Data!E7="F",Raw_Data!E7="Female"),"Female","Not Confirmed")) -> Female | I7: =Raw_Data!F7 -> 58 | J7: =FLOOR(Raw_Data!F7,10)&"-"&FLOOR(Raw_Data!F7,10)+9 -> 50-59 | K7: =Raw_Data!G7 -> White | L7: =Raw_Data!H7 -> General Practice | M7: =IF(Raw_Data!I7=TRUE,"Admitted","Not Admitted") -> Admitted | N7: =IF(Raw_Data!J7="","Not Rated",Raw_Data!J7) -> 0 | O7: =Raw_Data!K7 -> 27 | P7: =IF(Raw_Data!K7<=30,"Within Time","Delayed") -> Within Time
A8: =Raw_Data!A8 -> 855-20-3905 | B8: =Raw_Data!B8 -> 45017.331 | C8: =HOUR(Raw_Data!B8) -> 7 | D8: =TEXT(Raw_Data!B8,"mmm") -> Apr | E8: =YEAR(Raw_Data!B8) -> 2023 | F8: =TEXT(Raw_Data!B8,"mmm-yy") -> Apr-23 | G8: =PROPER(Raw_Data!C8&". "&Raw_Data!D8) -> F. Garfield | H8: =IF(OR(Raw_Data!E8="M",Raw_Data!E8="Male"),"Male",IF(OR(Raw_Data!E8="F",Raw_Data!E8="Female"),"Female","Not Confirmed")) -> Male | I8: =Raw_Data!F8 -> 14 | J8: =FLOOR(Raw_Data!F8,10)&"-"&FLOOR(Raw_Data!F8,10)+9 -> 10-19 | K8: =Raw_Data!G8 -> Two or More Races | L8: =Raw_Data!H8 -> None | M8: =IF(Raw_Data!I8=TRUE,"Admitted","Not Admitted") -> Admitted | N8: =IF(Raw_Data!J8="","Not Rated",Raw_Data!J8) -> 9 | O8: =Raw_Data!K8 -> 31 | P8: =IF(Raw_Data!K8<=30,"Within Time","Delayed") -> Delayed
A9: =Raw_Data!A9 -> 204-20-3676 | B9: =Raw_Data!B9 -> 45017.338 | C9: =HOUR(Raw_Data!B9) -> 8 | D9: =TEXT(Raw_Data!B9,"mmm") -> Apr | E9: =YEAR(Raw_Data!B9) -> 2023 | F9: =TEXT(Raw_Data!B9,"mmm-yy") -> Apr-23 | G9: =PROPER(Raw_Data!C9&". "&Raw_Data!D9) -> M. Stanlack | H9: =IF(OR(Raw_Data!E9="M",Raw_Data!E9="Male"),"Male",IF(OR(Raw_Data!E9="F",Raw_Data!E9="Female"),"Female","Not Confirmed")) -> Male | I9: =Raw_Data!F9 -> 55 | J9: =FLOOR(Raw_Data!F9,10)&"-"&FLOOR(Raw_Data!F9,10)+9 -> 50-59 | K9: =Raw_Data!G9 -> White | L9: =Raw_Data!H9 -> None | M9: =IF(Raw_Data!I9=TRUE,"Admitted","Not Admitted") -> Not Admitted | N9: =IF(Raw_Data!J9="","Not Rated",Raw_Data!J9) -> 7 | O9: =Raw_Data!K9 -> 44 | P9: =IF(Raw_Data!K9<=30,"Within Time","Delayed") -> Delayed
A10: =Raw_Data!A10 -> 716-23-4315 | B10: =Raw_Data!B10 -> 45017.374 | C10: =HOUR(Raw_Data!B10) -> 8 | D10: =TEXT(Raw_Data!B10,"mmm") -> Apr | E10: =YEAR(Raw_Data!B10) -> 2023 | F10: =TEXT(Raw_Data!B10,"mmm-yy") -> Apr-23 | G10: =PROPER(Raw_Data!C10&". "&Raw_Data!D10) -> L. Jessop | H10: =IF(OR(Raw_Data!E10="M",Raw_Data!E10="Male"),"Male",IF(OR(Raw_Data!E10="F",Raw_Data!E10="Female"),"Female","Not Confirmed")) -> Male | I10: =Raw_Data!F10 -> 43 | J10: =FLOOR(Raw_Data!F10,10)&"-"&FLOOR(Raw_Data!F10,10)+9 -> 40-49 | K10: =Raw_Data!G10 -> White | L10: =Raw_Data!H10 -> General Practice | M10: =IF(Raw_Data!I10=TRUE,"Admitted","Not Admitted") -> Not Admitted | N10: =IF(Raw_Data!J10="","Not Rated",Raw_Data!J10) -> 6 | O10: =Raw_Data!K10 -> 53 | P10: =IF(Raw_Data!K10<=30,"Within Time","Delayed") -> Delayed
A11: =Raw_Data!A11 -> 947-59-1554 | B11: =Raw_Data!B11 -> 45017.501 | C11: =HOUR(Raw_Data!B11) -> 12 | D11: =TEXT(Raw_Data!B11,"mmm") -> Apr | E11: =YEAR(Raw_Data!B11) -> 2023 | F11: =TEXT(Raw_Data!B11,"mmm-yy") -> Apr-23 | G11: =PROPER(Raw_Data!C11&". "&Raw_Data!D11) -> Q. Cholmondeley | H11: =IF(OR(Raw_Data!E11="M",Raw_Data!E11="Male"),"Male",IF(OR(Raw_Data!E11="F",Raw_Data!E11="Female"),"Female","Not Confirmed")) -> Female | I11: =Raw_Data!F11 -> 67 | J11: =FLOOR(Raw_Data!F11,10)&"-"&FLOOR(Raw_Data!F11,10)+9 -> 60-69 | K11: =Raw_Data!G11 -> Native American/Alaska Native | L11: =Raw_Data!H11 -> None | M11: =IF(Raw_Data!I11=TRUE,"Admitted","Not Admitted") -> Admitted | N11: =IF(Raw_Data!J11="","Not Rated",Raw_Data!J11) -> 2 | O11: =Raw_Data!K11 -> 16 | P11: =IF(Raw_Data!K11<=30,"Within Time","Delayed") -> Within Time
A12: =Raw_Data!A12 -> 466-34-9495 | B12: =Raw_Data!B12 -> 45017.617 | C12: =HOUR(Raw_Data!B12) -> 14 | D12: =TEXT(Raw_Data!B12,"mmm") -> Apr | E12: =YEAR(Raw_Data!B12) -> 2023 | F12: =TEXT(Raw_Data!B12,"mmm-yy") -> Apr-23 | G12: =PROPER(Raw_Data!C12&". "&Raw_Data!D12) -> M. Upperton | H12: =IF(OR(Raw_Data!E12="M",Raw_Data!E12="Male"),"Male",IF(OR(Raw_Data!E12="F",Raw_Data!E12="Female"),"Female","Not Confirmed")) -> Female | I12: =Raw_Data!F12 -> 20 | J12: =FLOOR(Raw_Data!F12,10)&"-"&FLOOR(Raw_Data!F12,10)+9 -> 20-29 | K12: =Raw_Data!G12 -> White | L12: =Raw_Data!H12 -> None | M12: =IF(Raw_Data!I12=TRUE,"Admitted","Not Admitted") -> Not Admitted | N12: =IF(Raw_Data!J12="","Not Rated",Raw_Data!J12) -> Not Rated | O12: =Raw_Data!K12 -> 30 | P12: =IF(Raw_Data!K12<=30,"Within Time","Delayed") -> Within Time
A13: =Raw_Data!A13 -> 706-60-4656 | B13: =Raw_Data!B13 -> 45017.778 | C13: =HOUR(Raw_Data!B13) -> 18 | D13: =TEXT(Raw_Data!B13,"mmm") -> Apr | E13: =YEAR(Raw_Data!B13) -> 2023 | F13: =TEXT(Raw_Data!B13,"mmm-yy") -> Apr-23 | G13: =PROPER(Raw_Data!C13&". "&Raw_Data!D13) -> R. Aldridge | H13: =IF(OR(Raw_Data!E13="M",Raw_Data!E13="Male"),"Male",IF(OR(Raw_Data!E13="F",Raw_Data!E13="Female"),"Female","Not Confirmed")) -> Male | I13: =Raw_Data!F13 -> 11 | J13: =FLOOR(Raw_Data!F13,10)&"-"&FLOOR(Raw_Data!F13,10)+9 -> 10-19 | K13: =Raw_Data!G13 -> Asian | L13: =Raw_Data!H13 -> None | M13: =IF(Raw_Data!I13=TRUE,"Admitted","Not Admitted") -> Not Admitted | N13: =IF(Raw_Data!J13="","Not Rated",Raw_Data!J13) -> Not Rated | O13: =Raw_Data!K13 -> 40 | P13: =IF(Raw_Data!K13<=30,"Within Time","Delayed") -> Delayed
... A9217: =Raw_Data!A9217 -> 894-63-9858 | B9217: =Raw_Data!B9217 -> 45595.918 | C9217: =HOUR(Raw_Data!B9217) -> 22 | D9217: =TEXT(Raw_Data!B9217,"mmm") -> Oct | E9217: =YEAR(Raw_Data!B9217) -> 2024 | F9217: =TEXT(Raw_Data!B9217,"mmm-yy") -> Oct-24 | G9217: =PROPER(Raw_Data!C9217&". "&Raw_Data!D9217) -> B. Upperton | H9217: =IF(OR(Raw_Data!E9217="M",Raw_Data!E9217="Male"),"Male",IF(OR(Raw_Data!E9217="F",Raw_Data!E9217="Female"),"Female","Not Confirmed")) -> Male | I9217: =Raw_Data!F9217 -> 22 | J9217: =FLOOR(Raw_Data!F9217,10)&"-"&FLOOR(Raw_Data!F9217,10)+9 -> 20-29 | K9217: =Raw_Data!G9217 -> Unknown | L9217: =Raw_Data!H9217 -> None | M9217: =IF(Raw_Data!I9217=TRUE,"Admitted","Not Admitted") -> Not Admitted | N9217: =IF(Raw_Data!J9217="","Not Rated",Raw_Data!J9217) -> Not Rated | O9217: =Raw_Data!K9217 -> 50 | P9217: =IF(Raw_Data!K9217<=30,"Within Time","Delayed") -> Delayed

Sheet Pivot_Tables
L1: All pivots share one cache (ERData) - slicers on Dashboard filter everything. | Z1: =TEXT(GETPIVOTDATA("Total Patients",$A$3),"#,##0") -> 9,216
Z2: =TEXT(GETPIVOTDATA("Avg Wait Time",$A$3),"0.0")&" min" -> 35.1 min
A3: Total Patients | B3: Avg Wait Time | C3: Avg Satisfaction | Z3: =TEXT(GETPIVOTDATA("Avg Satisfaction",$A$3),"0.0")&" / 10" -> 4.9 / 10
A4: 9216 | B4: 35.094835 | C4: 4.9113176 | Z4: =TEXT(IFERROR(GETPIVOTDATA("Total Patients",$J$8,"Patient Attend Status","Within Time")/GETPIVOTDATA("Total Patients",$J$8),0),"0.0%") -> 40.6%
A8: Row Labels | B8: Total Patients | D8: Row Labels | E8: Total Patients | G8: Row Labels | H8: Total Patients | J8: Row Labels | K8: Total Patients
A9: 0-9 | B9: 1035 | D9: Female | E9: 4326 | G9: Admitted | H9: 4577 | J9: Delayed | K9: 5470
A10: 10-19 | B10: 1260 | D10: Male | E10: 4791 | G10: Not Admitted | H10: 4639 | J10: Within Time | K10: 3746
A11: 20-29 | B11: 1134 | D11: Not Confirmed | E11: 99 | G11: Grand Total | H11: 9216 | J11: Grand Total | K11: 9216
A12: 30-39 | B12: 1082 | D12: Grand Total | E12: 9216
A13: 40-49 | B13: 1242
A14: 50-59 | B14: 1171
A15: 60-69 | B15: 1142
A16: 70-79 | B16: 1150
A17: Grand Total | B17: 9216
A25: Row Labels | B25: Total Patients | D25: Row Labels | E25: Total Patients | G25: Row Labels | H25: Total Patients
A26: None | B26: 5320 | D26: White | E26: 2401 | G26: 2023
A27: General Practice | B27: 1792 | D27: African American | E27: 1725 | G27: Apr | H27: 491
A28: Orthopedics | B28: 862 | D28: Unknown | E28: 1372 | G28: May | H28: 486
A29: Physiotherapy | B29: 503 | D29: Two or More Races | E29: 1028 | G29: Jun | H29: 484
A30: Gastroenterology | B30: 265 | D30: Asian | E30: 932 | G30: Jul | H30: 518
A31: Cardiology | B31: 186 | D31: Declined to Identify | E31: 894 | G31: Aug | H31: 507
A32: Neurology | B32: 174 | D32: Pacific Islander | E32: 570 | G32: Sep | H32: 474
A33: Renal | B33: 114 | D33: Native American/Alaska Native | E33: 294 | G33: Oct | H33: 481
A34: Grand Total | B34: 9216 | D34: Grand Total | E34: 9216 | G34: Nov | H34: 445
G35: Dec | H35: 482
G36: 2024
G37: Jan | H37: 487
G38: Feb | H38: 485
G39: Mar | H39: 525
G40: Apr | H40: 478
G41: May | H41: 466
G42: Jun | H42: 462
G43: Jul | H43: 551
G44: Aug | H44: 462
G45: Sep | H45: 465
G46: Oct | H46: 467
G47: Grand Total | H47: 9216

Sheet Dashboard
